#### 异常Exception

##### try、catch、finally、throw、throws

- throw用于在方法中抛出某个特定异常

- throws用于方法声明时，表示该方法可能抛出异常（一般是受检异常），调用者需要处理

  ```java
  public void test() throws IOException {
      throw new IOException;
  }
  ```

  

```java
try {
    //可能产生异常的代码
} catch(Ecceptin e) {
    //处理异常的代码
} finally {
    //无论是否发生异常，代码总能执行
}
```

```java
public static void main(String[] args) {
        int num1 = 10;
        int num2 = 0;
        try {
            int r = num1 / num2;
            System.out.println(r);
        } catch (Exception e) {
            e.printStackTrace();
        } finally {
            System.out.println("finally");
        }
    }
```

##### 多重catch

- 一段代码可能会引发多种类型的异常

- 当引发异常时，会按顺序来查看每个catch语句，并执行第一个与异常类型匹配的catch语句

- 执行其中一条catch语句后，其后catch语句将被忽略

  ```java
  public void method() {
      try {
          //代码块
          //产生异常（异常类型2）
      } catch (异常类型1 ex) {
          //对异常进行处理的代码块
      } catch (异常类型2 ex) {
          //对异常进行处理的代码块
      } catch (异常类型3 ex) {
          //对异常进行处理的代码块
      }
      //代码段
  }
  ```



##### 异常分类

- Checked Exception
  - 受检异常，Exception或其子类中不属于RuntimeException或其子类的异常
  - 需要处理，需要显式使用catch捕获或throws抛出
- Unchecked Exception
  - 非受检异常，也叫运行时异常
  - 程序可以不显式处理，交由JVM
  - Error及其子类，RuntimeException及其子类

##### 受检异常的处理

- 两种方式：

  - 使用try...catch显式处理

    ```java
    try {
        System.in.read();
    } catch (IOException e) {
        
    }
    ```

  - 在调用方法上使用throws向上抛出

    ```java
    public static void test() throws IOException {
    	System.in.read();
    }
    
    public static void main(String[] args) {
    	try{
    		test();
    	} catch (IOException e) {
                
    	}
    }
    ```

- 分别使用或同时使用都可以

- 注意：catch不能捕获try代码块中不会抛出的受检异常

###### 受检异常与初始化块

- 不可在静态初始化块中抛出受检异常，而需要使用try...catch处理
- 在实例初始化块中可以抛出异常，但是构造方法必须使用throws抛出

```java
public class ExceptionDemo3 {
    {//实例初始化块中异常可以try...catch也可以在构造方法throws
        System.in.read();
    }

    static {//静态初始化块异常只能用try...catch
        try {
            System.in.read();
        } catch (IOException e) {

        }
    }

    public ExceptionDemo3() throws IOException {//构造方法throws异常

    }
    
    public static void main(String[] args) {
        try {//这里也必须trt...catch，因为构造方法有throws异常
            ExceptionDemo3 ex = new ExceptionDemo3();
        } catch (IOException e) {
            
        }
    }
}
```

##### 自定义异常

现有的异常类不能满足问题的描述时，需要自定义异常

```java
public class MyException extends Exception {
    public MyException() {
    }

    public MyException(String msg) {
        super(msg);
    }
    
    public MyException(Throwable t) {
        super(t);
    }
    
    public MyException(String msg, Throwable t) {
        super(msg, t);
    }
}
```

```java
public class TestMyException {
    public void test(int num) throws MyException {
        if(num<10){
            throw new MyException("num小于10");
        }
    }
    
    public static void main(String[] args) {
        TestMyException test = new TestMyException();
        try {
            test.test(1);
        } catch (MyException e) {
            e.printStackTrace();
        }
    }
}
/*exception.MyException: num小于10
	at exception.TestMyException.test(TestMyException.java:8)
	at exception.TestMyException.main(TestMyException.java:15)*/
```



##### Throwable中的常用方法

| 方法                                 | 作用                                   |
| ------------------------------------ | -------------------------------------- |
| Throwable getCause()                 | 返回异常的原因，没有设置的话，返回null |
| String getMessage()                  | 返回异常的详细信息                     |
| Throwable initCause(Throwable cause) | 设置异常的原因，与构造方法类似         |
| void printStackTrace()               | 在标准输出设备上输出异常信息           |



##### 重新抛出异常

可能的原因：

- 在向上传播之前，先做一些处理
- 对客户端隐藏原始异常信息
- 分层结构中降低层之间的耦合度

```java
public void test() throws MyException {
    try {
        System.in.read();
    } catch (IOException e) {
        e.printStackTrace();
        throw new MyException("重新抛出异常");
    }
}
```

##### 异常链

1. 常常会再捕获一个异常后跑出另外一个异常，并且希望把异常原始信息保存下来，这被称为异常链。
2. 在JDK1.4以前，程序员必须自己编写代码来保存原始异常信息，
3. 现在所有Throwable的子类子构造器中都可以接受一个cause对象作为参数，这个cause就异常原由，代表着原始异常，即使在当前位置创建并抛出行的异常，也可以通过这个cause追踪到异常最初发生的位置。
4. Throwable类及其所有的子类都提供了带cause参数的构造器，其他的异常类就只有通过initCause()来设置cause了。

```java
public void test() throws MyException {
    try {
        System.in.read();
    } catch (IOException e) {
        e.printStackTrace();
        throw new MyException(e);//这里调用的是public MyException(Throwable t) { super(t);}这个构造函数
    }
}

public static void main(String[] args) {
    TestMyException test = new TestMyException();
    try {
        test.test();
    } catch (MyException2 e) {
        Throwable cause = e.getCause();
        if(cause instanceof MyException) {
            System.out.println("MyException");
        }
        e.printStackTrace();
    }
}
```

##### 方法重写与异常

子类方法重写时声明抛出的异常不能比父类方法声明的异常数量多或范围广